<?xml version="1.0"?>
<robot name="arm_robot">

  <material name="grey">
    <color rgba="0.5 0.5 0.5 1"/>
  </material>
  <material name="blue">
    <color rgba="0.2 0.2 0.8 1"/>
  </material>

  <link name="base_link">
    <visual>
      <origin xyz="0 0 0.026" rpy="0 0 0"/>
      <geometry>
        <cylinder length="0.052" radius="0.049"/>
      </geometry>
      <material name="grey"/>
    </visual>
  </link>

  <joint name="base_joint" type="revolute">
    <parent link="base_link"/>
    <child link="shoulder_link"/>
    <origin xyz="0 0 0.052" rpy="0 0 0"/>
    <axis xyz="0 0 1"/>
    <limit lower="-3.1415" upper="3.1415" effort="10" velocity="1.0"/>
  </joint>

  <link name="shoulder_link">
    <visual>
      <origin xyz="0.00875 0 0.018138" rpy="0 0 0"/>
      <geometry>
        <box size="0.035 0.06 0.036276"/>
      </geometry>
      <material name="grey"/>
    </visual>
  </link>

  <joint name="shoulder_joint" type="revolute">
    <parent link="shoulder_link"/>
    <child link="arm_1"/>
    <origin xyz="0.0175 0 0.036276" rpy="0 0 0"/>
    <axis xyz="0 1 0"/>
    <limit lower="-1.5708" upper="1.5708" effort="10" velocity="1.0"/>
  </joint>

  <link name="arm_1">
    <visual>
      <origin xyz="0 0 0.060725" rpy="0 0 0"/>
      <geometry>
        <box size="0.04 0.05 0.12145"/>
      </geometry>
      <material name="blue"/>
    </visual>
  </link>

  <joint name="elbow_joint" type="revolute">
    <parent link="arm_1"/>
    <child link="arm_2"/> 
    <origin xyz="0 0 0.12145" rpy="0 0 0"/>
    <axis xyz="0 1 0"/>
    <limit lower="-1.5708" upper="1.5708" effort="10" velocity="1.0"/>
  </joint>

  <link name="arm_2">
    <visual>
      <origin xyz="0 0 0.0910875" rpy="0 0 0"/>
      <geometry>
        <box size="0.035 0.045 0.182175"/>
      </geometry>
      <material name="grey"/>
    </visual>
  </link>

</robot>